Workbook

Sheet Claims
A1: video_id | B1: claim_id | C1: claim_text | D1: category | E1: time | F1: system_verdict | G1: confidence | H1: confidence_without_nli | I1: nli_agreement | J1: nli_adjustment | K1: conflict_capped | L1: n_sources | M1: summary | N1: cited_urls | O1: gold_label | P1: correct
A2: Og5xAdC8EUI | B2: 1 | C2: Humans eat on average between one and 2.7 kilograms of food a day. | D2: Health | E2: 00:07-00:13 | F2: TRUE | G2: 0.6 | H2: 0.562 | I2: 0.473 | J2: 0.0378 | K2: FALSE | L2: 5 | M2: Humans typically eat about 1–2.7 kg of food each day. | N2: https://www.precisionnutrition.com/what-are-your-4-lbs | O2: TRUE | P2: =IF(O2="","",IF(O2&""=F2&"",1,0)) -> 1
A3: Og5xAdC8EUI | B3: 2 | C3: The gastrointestinal tract has an internal surface area of between 30 and 40 square meters. | D3: Science | E3: 00:59-01:08 | F3: TRUE | G3: 0.901 | H3: 0.823 | I3: 0.981 | J3: 0.0785 | K3: FALSE | L3: 5 | M3: The gut’s inner surface area is roughly 30–40 m². | N3: https://en.wikipedia.org/wiki/Gastrointestinal_tract https://www.sciencedaily.com/releases/2014/04/140423111505.htm https://www.popsci.com/article/science/human-gut-has-surface-area-studio-apartment https://bionumbers.hms.harvard.edu/bionumber.aspx?s=n&v=5&id=111126 https://www.elegantexperiments.net/en/post/area-digestive-system | O3: TRUE | P3: =IF(O3="","",IF(O3&""=F3&"",1,0)) -> 1
A4: Og5xAdC8EUI | B4: 3 | C4: Humans produce about 1.5 liters of saliva each day. | D4: Health | E4: 01:47-01:52 | F4: TRUE | G4: 0.537 | H4: 0.51 | I4: 0.338 | J4: 0.027 | K4: TRUE | L4: 4 | M4: Humans produce roughly 1.5 L of saliva each day. | N4: https://en.wikipedia.org/wiki/Saliva https://pmc.ncbi.nlm.nih.gov/articles/PMC5052503 https://my.clevelandclinic.org/health/body/saliva https://ostrowonline.usc.edu/understanding-the-role-of-saliva | O4: TRUE | P4: =IF(O4="","",IF(O4&""=F4&"",1,0)) -> 1
A5: Og5xAdC8EUI | B5: 4 | C5: The esophagus is a 25‑centimeter‑long tube. | D5: Science | E5: 02:06-02:10 | F5: TRUE | G5: 0.791 | H5: 0.765 | I5: 0.325 | J5: 0.026 | K5: FALSE | L5: 5 | M5: The human esophagus is about 25 cm long. | N5: https://en.wikipedia.org/wiki/Esophagus https://hypertextbook.com/facts/2001/JenniferTran.shtml https://training.seer.cancer.gov/ugi/anatomy/esophagus.html https://emedicine.medscape.com/article/1948973-overview https://www.leading-medicine-guide.com/en/anatomy/esophagus | O5: TRUE | P5: =IF(O5="","",IF(O5&""=F5&"",1,0)) -> 1
A6: Og5xAdC8EUI | B6: 5 | C6: The digestive process typically lasts between 30 and 40 hours. | D6: Health | E6: 04:33-04:38 | F6: UNVERIFIABLE | G6: 0 | H6: 0 | L6: 5 | M6: The claim that digestion usually takes 30‑40 hours is not consistently backed by the sources. | N6: https://www.bodyspec.com/blog/post/normal_transit_time_for_food_and_digestion_duration_explained https://www.ucsfhealth.org/care/medical-tests/bowel-transit-time https://acibademinternational.com/blog/how-long-does-it-take-to-digest-food-a-journey-measured-in-hours https://www.healthline.com/health/how-long-does-it-take-to-digest-food https://health.clevelandclinic.org/how-long-does-it-take-to-digest-food | O6: TRUE | P6: =IF(O6="","",IF(O6&""=F6&"",1,0)) -> 0
A7: bsAWFKZPntY | B7: 1 | C7: Waking a sleepwalker is not dangerous. | D7: Health | E7: 00:00-00:05 | F7: TRUE | G7: 0.865 | H7: 0.833 | I7: 0.407 | J7: 0.0326 | K7: FALSE | L7: 5 | M7: Waking a sleepwalker is not dangerous. | N7: https://www.bbc.com/future/article/20120208-it-is-dangerous-to-wake-a-sleepwa https://nymetrosleep.com/blog/sleepwalking-and-sleep-health-myths-risks-and-expert-advice https://uamshealth.com/medical-myths/is-it-dangerous-to-wake-a-sleepwalker https://www.sleepfoundation.org/parasomnias/what-happens-if-you-wake-a-sleepwalker https://www.baptisthealth.com/blog/health-and-wellness/how-to-safely-wake-a-sleepwalker | O7: TRUE | P7: =IF(O7="","",IF(O7&""=F7&"",1,0)) -> 1
A8: bsAWFKZPntY | B8: 2 | C8: Bulls are colorblind to red and charge at the movement of a matador's cape, not its color. | D8: Science | E8: 00:07-00:15 | F8: TRUE | G8: 0.852 | H8: 0.812 | I8: 0.496 | J8: 0.0397 | K8: FALSE | L8: 5 | M8: Bulls are colorblind to red and charge at a moving cape, not its color. | N8: https://www.westeamahead.org/blog/2025/12/11/mythbuster-do-bulls-hate-the-color-red https://www.instagram.com/reel/DV87wgniOcu?hl=en https://www.youtube.com/watch?v=vCFyl70n19M https://capes.com/blogs/cape-facts/why-do-matadors-use-red-capes https://www.livescience.com/33700-bulls-charge-red.html | O8: TRUE | P8: =IF(O8="","",IF(O8&""=F8&"",1,0)) -> 1
A9: bsAWFKZPntY | B9: 3 | C9: Dropping a penny from a skyscraper cannot kill someone, mainly because of air resistance. | D9: Science | E9: 00:19-00:27 | F9: TRUE | G9: 0.851 | H9: 0.812 | I9: 0.48 | J9: 0.0384 | K9: FALSE | L9: 4 | M9: A penny dropped from a skyscraper can’t kill you because air resistance limits its speed. | N9: https://www.scientificamerican.com/article/could-a-penny-dropped-off https://www.wtamu.edu/~cbaird/sq/2012/12/10/how-high-does-a-building-have-to-be-for-a-penny-dropped-from-the-top-to-kill-a-person-on-the-ground https://www.youtube.com/watch?v=16Ci_2bN_zc | O9: TRUE | P9: =IF(O9="","",IF(O9&""=F9&"",1,0)) -> 1
A10: bsAWFKZPntY | B10: 4 | C10: Humans did not evolve from modern monkeys; we share a common ancestor but evolved on separate branches of the evolutionary tree. | D10: History | E10: 00:37-00:47 | F10: TRUE | G10: 0.827 | H10: 0.812 | I10: 0.187 | J10: 0.015 | K10: FALSE | L10: 5 | M10: Humans did not evolve from modern monkeys; we share a common ancestor and diverged on separate branches. | N10: https://friendsofdarwin.com/articles/why-still-monkeys https://www.pbs.org/wgbh/evolution/library/faq/cat02.html https://ncse.ngo/misconception-monday-lets-stop-monkeying-about-shall-we https://humanorigins.si.edu/education/frequently-asked-questions | O10: TRUE | P10: =IF(O10="","",IF(O10&""=F10&"",1,0)) -> 1
A11: bsAWFKZPntY | B11: 5 | C11: The Earth's core is not molten lava; it is liquid metal (mostly iron and nickel) with a solid inner core. | D11: Science | E11: 02:17-02:27 | F11: TRUE | G11: 0.837 | H11: 0.767 | I11: 0.883 | J11: 0.0707 | K11: FALSE | L11: 5 | M11: The Earth's core is a liquid iron‑nickel outer core with a solid inner core, not molten lava. | N11: https://www.nsf.gov/news/seismologists-peer-earths-inner-core https://en.wikipedia.org/wiki/Earth%27s_inner_core https://pmc.ncbi.nlm.nih.gov/articles/PMC4040578 https://www.ebsco.com/research-starters/earth-and-atmospheric-sciences/outer-core https://www.scientificamerican.com/article/earths-inner-core-may-have-an-inner-core | O11: TRUE | P11: =IF(O11="","",IF(O11&""=F11&"",1,0)) -> 1
A12: QqsLTNkzvaY | B12: 1 | C12: A black hole with ten times the mass of the Sun would be barely 60 km across. | D12: Science | E12: 01:33-01:45 | F12: TRUE | G12: 0.633 | H12: 0.633 | K12: FALSE | L12: 5 | M12: A 10‑solar‑mass black hole would be about 60 km across. | N12: http://blackholes.stardate.org/objects/type-stellar-mass.html https://www.sun.org/encyclopedia/black-hole https://www.youtube.com/watch?v=yrQZi02LKQY https://www.firgelliauto.com/blogs/engineering-calculators/schwarzschild-radius-calculator https://www.omnicalculator.com/physics/schwarzschild-radius | O12: TRUE | P12: =IF(O12="","",IF(O12&""=F12&"",1,0)) -> 1
A13: QqsLTNkzvaY | B13: 2 | C13: A black hole with the mass of our Sun has a lifetime of about 10^67 years. | D13: Science | E13: 09:32-09:48 | F13: TRUE | G13: 0.654 | H13: 0.654 | K13: FALSE | L13: 5 | M13: A black‑hole the size of the Sun would evaporate in roughly 10⁶⁷ years. | N13: https://jila.colorado.edu/~ajsh/bh/hawk.html https://www.youtube.com/watch?v=MJb6colKwzo https://www.discovermagazine.com/black-holes-can-die-but-the-process-hawking-radiation-is-incredibly-slow-47996 | O13: TRUE | P13: =IF(O13="","",IF(O13&""=F13&"",1,0)) -> 1
A14: QqsLTNkzvaY | B14: 3 | C14: The most massive super‑massive black holes in galaxy centers have lifetimes of roughly 10^100 years. | D14: Science | E14: 09:56-10:08 | F14: TRUE | G14: 0.825 | H14: 0.825 | K14: FALSE | L14: 5 | M14: Supermassive black holes are expected to live about 10^100 years before evaporating. | N14: https://en.wikipedia.org/wiki/Hawking_radiation https://www.astronomy.com/science/the-beginning-to-the-end-of-the-universe-how-black-holes-die https://www.discovermagazine.com/black-holes-can-die-but-the-process-hawking-radiation-is-incredibly-slow-47996 https://www.youtube.com/watch?v=MJb6colKwzo | O14: TRUE | P14: =IF(O14="","",IF(O14&""=F14&"",1,0)) -> 1
A15: QqsLTNkzvaY | B15: 4 | C15: A black hole has only three observable properties: its mass, its spin, and its electric charge. | D15: Science | E15: 06:09-06:19 | F15: TRUE | G15: 0.825 | H15: 0.825 | K15: FALSE | L15: 5 | M15: Black holes are described by only three observable properties: mass, spin, and charge. | N15: https://arxiv.org/html/2309.14929v2 https://en.wikipedia.org/wiki/No-hair_theorem https://www.quantamagazine.org/in-violation-of-einstein-black-holes-might-have-hair-20210211 https://www.youtube.com/watch?v=oi4LAbTKqBI https://heasarc.gsfc.nasa.gov/docs/objects/heapow/archive/compact_objects/spinning_bh_chandra.html | O15: TRUE | P15: =IF(O15="","",IF(O15&""=F15&"",1,0)) -> 1
A16: QqsLTNkzvaY | B16: 5 | C16: Spaghettification is only a risk with smaller black holes because they have a much smaller radius. | D16: Science | E16: 04:06-04:14 | F16: TRUE | G16: 0.79 | H16: 0.79 | K16: FALSE | L16: 5 | M16: Spaghettification is mainly a danger near small black holes, not large ones. | N16: https://en.wikipedia.org/wiki/Spaghettification https://www.scienceholic.org/post/spaghettification-the-cosmic-pasta-maker https://physics.stackexchange.com/questions/856047/why-do-people-use-this-argument-for-how-a-black-hole-would-turn-me-into-spaghett | O16: TRUE | P16: =IF(O16="","",IF(O16&""=F16&"",1,0)) -> 1
A17: PSRJfaAYkW4 | B17: 1 | C17: There are between 4,000 and 11,000 leukocytes in every microliter of blood. | D17: Health | E17: 01:08-01:17 | F17: TRUE | G17: 0.812 | H17: 0.812 | K17: FALSE | L17: 5 | M17: Normal blood contains about 4,000‑11,000 leukocytes per microliter. | N17: https://www.thebloodproject.com/understanding-leukocytosis https://ada.com/white-blood-cell-count https://news.cuanschutz.edu/news-stories/high-or-low-white-blood-cell-count-understanding-your-cbc-blood-test-results https://www.bannerhealth.com/healthcareblog/teach-me/why-is-my-white-blood-cell-count-high | O17: TRUE | P17: =IF(O17="","",IF(O17&""=F17&"",1,0)) -> 1
A18: PSRJfaAYkW4 | B18: 2 | C18: Leukocytes originate in the bone marrow. | D18: Health | E18: 00:58-01:00 | F18: TRUE | G18: 0.787 | H18: 0.787 | K18: FALSE | L18: 5 | M18: Leukocytes are produced in the bone marrow. | N18: https://en.wikipedia.org/wiki/White_blood_cell https://courses.lumenlearning.com/suny-ap2/chapter/leukocytes-and-platelets https://www.physio-pedia.com/Leukocytes https://my.clevelandclinic.org/health/articles/24287-hematopoiesis https://www.urmc.rochester.edu/encyclopedia/content?ContentID=35&ContentTypeID=160 | O18: TRUE | P18: =IF(O18="","",IF(O18&""=F18&"",1,0)) -> 1
A19: PSRJfaAYkW4 | B19: 3 | C19: A warmer body makes it harder for bacteria and viruses to reproduce and spread because they are temperature‑sensitive. | D19: Science | E19: 03:16-03:24 | F19: TRUE | G19: 0.6 | H19: 0.6 | K19: TRUE | L19: 5 | M19: Warmer body temperatures can hinder the growth of many bacteria and viruses. | N19: https://pubmed.ncbi.nlm.nih.gov/32776651 https://www.frontiersin.org/journals/cellular-and-infection-microbiology/articles/10.3389/fcimb.2026.1866500/full https://theconversation.com/how-does-fever-help-fight-infections-theres-more-to-it-than-even-some-scientists-realize-210240 https://www.pihealthcancerhospital.com/blog/the-connection-between-fever-and-infection-what-you-need-to-know https://pmc.ncbi.nlm.nih.gov/articles/PMC7435572 | O19: TRUE | P19: =IF(O19="","",IF(O19&""=F19&"",1,0)) -> 1
A20: PSRJfaAYkW4 | B20: 4 | C20: A healthy immune system will successfully fight off an estimated 300 colds over the course of a lifetime. | D20: Health | E20: 04:44-04:54 | F20: UNVERIFIABLE | G20: 0 | H20: 0 | L20: 5 | M20: There's no evidence that a healthy immune system prevents exactly 300 colds in a lifetime. | N20: https://www.cdc.gov/common-cold/about/index.html https://www.webmd.com/cold-and-flu/common_cold_overview https://www.yalemedicine.org/conditions/colds https://www.unionmillpediatrics.com/storage/app/media/frequent-colds.pdf https://www.today.com/health/cold-flu/why-do-i-keep-getting-colds-rcna48315 | O20: UNVERIFIABLE | P20: =IF(O20="","",IF(O20&""=F20&"",1,0)) -> 1
A21: PSRJfaAYkW4 | B21: 5 | C21: Autoimmune diseases underlie problems such as arthritis, Type I diabetes, and multiple sclerosis. | D21: Health | E21: 04:31-04:42 | F21: TRUE | G21: 0.723 | H21: 0.723 | K21: FALSE | L21: 5 | M21: Yes, arthritis, Type I diabetes and multiple sclerosis are all autoimmune diseases. | N21: https://www.aiarthritis.org/co-existing-conditions- https://www.hopkinsmedicine.org/health/expert-qa/autoimmune-disease-and-women https://health.ucdavis.edu/blog/cultivating-health/6-common-types-of-arthritis-and-related-conditions-symptoms-causes-and-risk-factors/2024/04 https://pmc.ncbi.nlm.nih.gov/articles/PMC4219937 https://pro.campus.sanofi/t1d/articles/the-pathophysiology-of-autoimmune-type-1-diabetes | O21: TRUE | P21: =IF(O21="","",IF(O21&""=F21&"",1,0)) -> 1
A22: rb7TVW77ZCs | B22: 1 | C22: In 1796, Edward Jenner injected material from a cowpox virus into an eight‑year‑old boy. | D22: History | E22: 00:07-00:17 | F22: TRUE | G22: 0.85 | H22: 0.85 | K22: FALSE | L22: 4 | M22: Yes, Jenner gave a cowpox inoculation to an eight‑year‑old boy in 1796. | N22: https://www.bbc.co.uk/history/historic_figures/jenner_edward.shtml https://en.wikipedia.org/wiki/Edward_Jenner https://www.ebsco.com/research-starters/history/jenner-develops-smallpox-vaccination https://pmc.ncbi.nlm.nih.gov/articles/PMC11463195 | O22: TRUE | P22: =IF(O22="","",IF(O22&""=F22&"",1,0)) -> 1
A23: rb7TVW77ZCs | B23: 2 | C23: The inoculation of the eight‑year‑old boy was the first ever vaccine. | D23: History | E23: 00:27-00:30 | F23: TRUE | G23: 0.831 | H23: 0.831 | K23: FALSE | L23: 5 | M23: Yes, that inoculation was the world’s first vaccine. | N23: https://www.who.int/news-room/spotlight/history-of-vaccination/a-brief-history-of-vaccination https://en.wikipedia.org/wiki/Edward_Jenner https://www.immunize.org/vaccines/vaccine-timeline https://vaccination-info.europa.eu/en/about-vaccines/history-vaccination https://biotech.law.lsu.edu/cphl/history/articles/jenner.htm | O23: TRUE | P23: =IF(O23="","",IF(O23&""=F23&"",1,0)) -> 1
A24: rb7TVW77ZCs | B24: 3 | C24: Live attenuated vaccines are made of the pathogen itself but a much weaker and tamer version. | D24: Science | E24: 02:16-02:29 | F24: TRUE | G24: 0.853 | H24: 0.853 | K24: FALSE | L24: 5 | M24: Live attenuated vaccines are made from the original pathogen that’s been weakened. | N24: https://www.sciencedirect.com/topics/immunology-and-microbiology/attenuated-vaccine https://en.wikipedia.org/wiki/Attenuated_vaccine https://www.pfizer.com/news/articles/understanding_six_types_of_vaccine_technologies https://synapse.patsnap.com/article/what-live-attenuated-vaccine-are-being-developed https://www.news-medical.net/health/What-is-a-Live-Attenuated-Vaccine.aspx | O24: TRUE | P24: =IF(O24="","",IF(O24&""=F24&"",1,0)) -> 1
A25: rb7TVW77ZCs | B25: 4 | C25: Inactive (killed) vaccines don’t create long‑lasting immunity. | D25: Health | E25: 02:53-03:00 | F25: TRUE | G25: 0.84 | H25: 0.84 | K25: FALSE | L25: 5 | M25: Inactivated vaccines generally do not provide long‑lasting immunity. | N25: https://www.cdc.gov/pinkbook/hcp/table-of-contents/chapter-1-principles-of-vaccination.html https://synapse.patsnap.com/article/what-is-the-difference-between-live-attenuated-and-inactivated-vaccines https://www.hhs.gov/vaccines/basics/types/index.html https://galvdox.galvmed.org/application/files/4116/6627/9827/177_Duration_of_Immunity_of_Live_and_Inactivated_ND_Vaccines_in_SPF_Chickens_FINAL_VERSION_011221.pdf https://www.clinicbarcelona.org/en/assistance/be-healthy/vaccine-1/when-do-vaccines-take-effect-and-what-is-the-duration | O25: UNVERIFIABLE | P25: =IF(O25="","",IF(O25&""=F25&"",1,0)) -> 0
A26: rb7TVW77ZCs | B26: 5 | C26: DNA vaccines work by injecting genes that instruct cells to make the antigens, triggering an immune response. | D26: Technology | E26: 03:25-03:44 | F26: TRUE | G26: 0.825 | H26: 0.825 | K26: FALSE | L26: 5 | M26: DNA vaccines work by injecting DNA that tells cells to make the antigen, which then triggers an immune response. | N26: https://en.wikipedia.org/wiki/DNA_vaccine https://www.frontiersin.org/journals/immunology/articles/10.3389/fimmu.2024.1332939/full https://pmc.ncbi.nlm.nih.gov/articles/PMC10820593 https://www.youtube.com/watch?v=H7_oL8mhtak | O26: TRUE | P26: =IF(O26="","",IF(O26&""=F26&"",1,0)) -> 1
A27: iNrUpBwU3q0 | B27: 1 | C27: The thyroid produces the hormones thyroxine (T4) and triiodothyronine (T3). | D27: Health | E27: 00:39-00:48 | F27: TRUE | G27: 0.777 | H27: 0.777 | K27: FALSE | L27: 5 | M27: The thyroid makes both T4 and T3. | N27: https://www.everlywell.com/blog/thyroid/t3-and-t4-hormones https://my.clevelandclinic.org/health/articles/22391-thyroid-hormone https://www.thyroid.org/thyroid-function-tests https://myhealth.alberta.ca/Health/pages/conditions.aspx?hwid=ug1836 https://www.youtube.com/watch?v=hKdqqaiNqis | O27: TRUE | P27: =IF(O27="","",IF(O27&""=F27&"",1,0)) -> 1
A28: iNrUpBwU3q0 | B28: 2 | C28: The pituitary gland controls the thyroid by releasing thyroid‑stimulating hormone (TSH) when blood hormone levels are too low or too high. | D28: Health | E28: 01:24-01:46 | F28: UNVERIFIABLE | G28: 0 | H28: 0 | L28: 5 | M28: There isn't enough verifiable evidence to support a verdict. | N28: https://www.sciencedirect.com/science/article/pii/S0303720721000174 https://www.healthywa.wa.gov.au/Articles/S_T/The-thyroid-gland https://www.thyroid.org/patient-thyroid-information/ct-for-patients/vol-5-issue-9/vol-5-issue-9-p-6-7 https://exeltis.com/sumtrial/category/blog/thyroid-hormones-functions-normal-levels-and-regulation https://www.yourhormones.info/hormones/thyroid-stimulating-hormone | O28: TRUE | P28: =IF(O28="","",IF(O28&""=F28&"",1,0)) -> 0
A29: iNrUpBwU3q0 | B29: 3 | C29: Hyperthyroidism occurs when the thyroid releases excess hormones, causing increased metabolism, faster heartbeat, constant hunger, rapid weight loss, heat intolerance, sweating, anxiety, and insomnia. | D29: Health | E29: 02:02-02:32 | F29: TRUE | G29: 0.581 | H29: 0.581 | K29: TRUE | L29: 5 | M29: Hyperthyroidism does cause the listed symptoms. | N29: https://ethosendo.com/blog/important-cardiac-effects-of-hyperthyroidism https://phoenixheart.com/how-high-thyroid-levels-affect-the-heart https://my.clevelandclinic.org/health/diseases/14129-hyperthyroidism https://www.childrenshospital.org/conditions-treatments/hyperthyroidism https://www.youtube.com/watch?v=wGkcusHjy_c | O29: TRUE | P29: =IF(O29="","",IF(O29&""=F29&"",1,0)) -> 1
A30: iNrUpBwU3q0 | B30: 4 | C30: Hypothyroidism occurs when the thyroid releases insufficient hormones, leading to weight gain, sluggishness, cold intolerance, joint swelling, and low mood. | D30: Health | E30: 02:32-02:57 | F30: UNVERIFIABLE | G30: 0 | H30: 0 | L30: 5 | M30: The claim is not fully verified. | N30: https://medicines.abbott.com/feeling-sluggish-and-cold-is-it-your-thyroid https://www.yalemedicine.org/conditions/hypothyroidism https://www.mdanderson.org/cancerwise/signs-of-thyroid-issues--hypothyroidism-hyperthyroidism-how-do-you-know-if-you-have-them.h00-159622590.html https://www.health.harvard.edu/newsletter_article/the-lowdown-on-thyroid-slowdown https://www.thyroid.org/wp-content/uploads/patients/brochures/Hypo_brochure.pdf | O30: TRUE | P30: =IF(O30="","",IF(O30&""=F30&"",1,0)) -> 0
A31: iNrUpBwU3q0 | B31: 5 | C31: Medical treatments can reactivate thyroid activity and restore a steady metabolic rate. | D31: Health | E31: 02:57-03:05 | F31: UNVERIFIABLE | G31: 0 | H31: 0 | L31: 5 | M31: Treatments can normalize thyroid hormone levels but don’t reactivate the gland itself. | N31: https://www.mayoclinic.org/diseases-conditions/hypothyroidism/diagnosis-treatment/drc-20350289 https://my.clevelandclinic.org/health/diseases/12120-hypothyroidism https://www.hopkinslupus.org/lupus-treatment/common-medications-conditions/thyroid-medications https://www.everlywell.com/blog/blood-test/thyroid-stimulating-hormone https://www.aafp.org/afp/2021/0515/p605 | O31: TRUE | P31: =IF(O31="","",IF(O31&""=F31&"",1,0)) -> 0
A32: yxonJTWhBJQ | B32: 1 | C32: Rhinovirus is responsible for up to half of all cases of the common cold. | D32: Health | E32: 01:36-01:48 | F32: TRUE | G32: 0.812 | H32: 0.812 | K32: FALSE | L32: 5 | M32: Rhinovirus causes about half of common colds. | N32: https://my.clevelandclinic.org/health/diseases/12342-common-cold https://www.biomerieux.com/us/en/blog/diagnostic-digest/human-rhinovirus.html https://www.youtube.com/watch?v=UW06euRm09Q https://pmc.ncbi.nlm.nih.gov/articles/PMC7112468 https://www.merckmanuals.com/professional/infectious-diseases/respiratory-viruses/common-cold | O32: TRUE | P32: =IF(O32="","",IF(O32&""=F32&"",1,0)) -> 1
A33: yxonJTWhBJQ | B33: 2 | C33: The trade‑off hypothesis was first developed in the early 1980s. | D33: Science | E33: 03:11-03:12 | F33: UNVERIFIABLE | G33: 0 | H33: 0 | L33: 5 | M33: No evidence that the trade‑off hypothesis originated in the early 1980s. | O33: TRUE | P33: =IF(O33="","",IF(O33&""=F33&"",1,0)) -> 0
A34: yxonJTWhBJQ | B34: 3 | C34: The malaria parasite Plasmodium is transmitted to humans by mosquito bites. | D34: Health | E34: 03:50-03:58 | F34: TRUE | G34: 0.78 | H34: 0.78 | K34: FALSE | L34: 5 | M34: True – Plasmodium is spread to people by mosquito bites. | N34: https://en.wikipedia.org/wiki/Malaria https://www.frontiersin.org/journals/malaria/articles/10.3389/fmala.2025.1600850/full https://www.mayoclinic.org/diseases-conditions/malaria/symptoms-causes/syc-20351184 https://pmc.ncbi.nlm.nih.gov/articles/PMC5891056 https://healthclinics.superdrug.com/is-malaria-contagious | O34: TRUE | P34: =IF(O34="","",IF(O34&""=F34&"",1,0)) -> 1
A35: yxonJTWhBJQ | B35: 4 | C35: Evolutionary biologist Paul Ewald has suggested that simple disease‑control measures can steer the evolution of pathogens toward less harmful forms. | D35: Science | E35: 04:16-04:24 | F35: TRUE | G35: 0.629 | H35: 0.629 | K35: FALSE | L35: 5 | M35: True – Ewald has argued that interventions can push pathogens to become less harmful. | N35: https://www.sciencedirect.com/science/article/abs/pii/S1567134808001809 https://en.wikipedia.org/wiki/Evolution_of_Infectious_Disease https://profiles.louisville.edu/pw.ewald/publications https://www.pbs.org/wgbh/evolution/library/01/6/text_pop/l_016_06.html https://math.uchicago.edu/~shmuel/Modeling/Evolution%20of%20virulence.pdf | O35: TRUE | P35: =IF(O35="","",IF(O35&""=F35&"",1,0)) -> 1
A36: yxonJTWhBJQ | B36: 5 | C36: The common cold is generally mild and typically lasts about one week. | D36: Health | E36: 03:38-03:46 | F36: TRUE | G36: 0.446 | H36: 0.446 | K36: TRUE | L36: 5 | M36: The claim is true: a common cold is usually mild and lasts about a week. | N36: https://www.aarp.org/health/conditions-treatments/how-long-does-a-cold-last https://www.everydayhealth.com/cold-flu/treatment/your-day-to-day-guide-to-the-common-cold https://www.healthline.com/health/life-cycle-of-the-common-cold https://www.goodrx.com/conditions/cold-symptoms/common-cold-stages-timeline https://www.christushealth.org/connect/your-health/infectious-diseases/stages-of-the-common-cold | O36: TRUE | P36: =IF(O36="","",IF(O36&""=F36&"",1,0)) -> 1
A37: vHhn7z6BA0w | B37: 1 | C37: The average man can throw a ball farther than about 98 percent of all women. | D37: Science | E37: 01:04-01:11 | F37: UNVERIFIABLE | G37: 0 | H37: 0 | L37: 5 | M37: We can’t verify that men out‑throw 98 % of women. | N37: https://pmc.ncbi.nlm.nih.gov/articles/PMC6657012 https://www.reddit.com/r/explainlikeimfive/comments/28hmk4/eli5_why_do_males_and_females_typically_throw https://www.worldpulse.org/story/girls-can-throw-and-girls-do-throw-better-than-boys-boys-however-refuse-to-admit-it-69626 | O37: TRUE | P37: =IF(O37="","",IF(O37&""=F37&"",1,0)) -> 0
A38: vHhn7z6BA0w | B38: 2 | C38: On average, women outperform about 33 percent of men in spatial awareness tasks such as map reading. | D38: Science | E38: 01:26-01:34 | F38: FALSE | G38: 0.696 | H38: 0.696 | K38: FALSE | L38: 5 | M38: Women do not outperform 33 % of men on spatial tasks. | N38: https://pmc.ncbi.nlm.nih.gov/articles/PMC6591491 https://news.emory.edu/stories/2019/04/gender-gap-spatial-reasoning-starts-elementary-school-meta-analysis-finds https://www.reddit.com/r/psychology/comments/bcd3o1/on_average_men_outperform_women_on_a_spatial | O38: TRUE | P38: =IF(O38="","",IF(O38&""=F38&"",1,0)) -> 0
A39: vHhn7z6BA0w | B39: 3 | C39: Rorschach inkblot tests have essentially no validity for diagnosing personality and are not used by modern psychologists. | D39: Science | E39: 03:16-03:24 | F39: FALSE | G39: 0.571 | H39: 0.571 | K39: TRUE | L39: 5 | M39: The claim is false; Rorschach tests still have modest validity and are still used by many psychologists. | N39: https://en.wikipedia.org/wiki/Rorschach_test https://pmc.ncbi.nlm.nih.gov/articles/PMC9225754 https://assets.noviams.com/novi-file-uploads/spa/PDFs___Documents/Articles_of_Interest/SPA__2005__JPA__Status_of_the_Rorschach1-983dc724.pdf https://www.ebsco.com/research-starters/health-and-medicine/rorschach-test https://www.bps.org.uk/psychologist/rorschach-test-100 | O39: FALSE | P39: =IF(O39="","",IF(O39&""=F39&"",1,0)) -> 1
A40: vHhn7z6BA0w | B40: 4 | C40: Learning styles are a myth and are not supported by scientific evidence. | D40: Science | E40: 04:25-04:29 | F40: TRUE | G40: 0.829 | H40: 0.829 | K40: FALSE | L40: 5 | M40: The claim is true; scientific research finds no evidence that learning styles improve learning. | N40: https://en.wikipedia.org/wiki/Learning_styles https://career.ucsf.edu/sites/g/files/tkssra15591/files/Article%20UCSF%20SEJC%20January%202017.pdf https://poorvucenter.yale.edu/teaching/teaching-resource-library/learning-styles-as-a-myth | O40: TRUE | P40: =IF(O40="","",IF(O40&""=F40&"",1,0)) -> 1
...

Sheet Metrics
A1: Accuracy (labelled claims) | B1: =IFERROR(SUM(Claims!P:P)/COUNT(Claims!P:P),"") -> 0.76923077
A3: Class | B3: Predicted | C3: Gold | D3: TP | E3: Precision | F3: Recall
A4: TRUE | B4: {=SUMPRODUCT((Claims!$F$2:$F$490&""=A4)*(Claims!$O$2:$O$490&""<>""))} -> 31 | C4: {=SUMPRODUCT(--(Claims!$O$2:$O$500&""=A4))} -> 36 | D4: {=SUMPRODUCT((Claims!$F$2:$F$500&""=A4)*(Claims!$O$2:$O$500&""=A4))} -> 29 | E4: =IFERROR(D4/B4,"") -> 0.93548387 | F4: =IFERROR(D4/C4,"") -> 0.80555556
A5: FALSE | B5: {=SUMPRODUCT((Claims!$F$2:$F$490&""=A5)*(Claims!$O$2:$O$490&""<>""))} -> 21 | C5: {=SUMPRODUCT(--(Claims!$O$2:$O$490&""=A5))} -> 16 | D5: =COUNTIFS(Claims!F:F,A5,Claims!O:O,A5) -> 0 | E5: =IFERROR(D5/B5,"") -> 0 | F5: =IFERROR(D5/C5,"") -> 0
A6: UNVERIFIABLE | B6: {=SUMPRODUCT((Claims!$F$2:$F$490&""=A6)*(Claims!$O$2:$O$490&""<>""))} -> 13 | C6: {=SUMPRODUCT(--(Claims!$O$2:$O$490&""=A6))} -> 13 | D6: =COUNTIFS(Claims!F:F,A6,Claims!O:O,A6) -> 6 | E6: =IFERROR(D6/B6,"") -> 0.46153846 | F6: =IFERROR(D6/C6,"") -> 0.46153846
A8: Mean confidence | B8: With NLI | C8: Without NLI
A9: Correct verdicts | B9: =IFERROR(AVERAGEIFS(Claims!G:G,Claims!P:P,1),"") -> 0.66248 | C9: =IFERROR(AVERAGEIFS(Claims!H:H,Claims!P:P,1),"") -> 0.65518
A10: Incorrect verdicts | B10: =IFERROR(AVERAGEIFS(Claims!G:G,Claims!P:P,0),"") -> 0.3668 | C10: =IFERROR(AVERAGEIFS(Claims!H:H,Claims!P:P,0),"") -> 0.3668
A11: Gap (correct - incorrect) | B11: =IFERROR(B9-B10,"") -> 0.29568 | C11: =IFERROR(C9-C10,"") -> 0.28838
